Workbook

Sheet Inputs
A1: Andover Community Netball Hub — model inputs
A2: Scenario (1 = Low, 2 = Base, 3 = High) | C2: 2
A3: Structure (1 = Ltd co, 2 = CIC, 3 = Charity/CIO, 4 = CASC) | C3: 2
A4: Yellow = edit. Green = active value used by every other sheet. Amounts are £ per year unless stated.
A5: Input | B5: Low | C5: Base | D5: High | E5: Active | F5: Note / source
A6: Facility
A7: Netball courts (one per 20 m span; a 4th fits the east block at league run-offs, in place of padel) | B7: 3 | C7: 3 | D7: 4 | E7: =CHOOSE($C$2,B7,C7,D7) | F7: Hollis survey: column rows at 20 m, frames at 7.5 m
A8: Padel courts (21 m spans only: 3 in the east block, 2 south of Court 3) | B8: 4 | C8: 5 | D8: 5 | E8: =CHOOSE($C$2,B8,C8,D8) | F8: LTA: 6 m sides, 8 m at ridge. Needs the 75 m line clear.
A9: Pickleball courts (span B end, 18 m x 20 m takes 2) | B9: 2 | C9: 2 | D9: 2 | E9: =CHOOSE($C$2,B9,C9,D9) | F9: 18.3 x 9.1 m each, 5.5 m height. Cheap to mark, fast-growing daytime demand
A10: Winter cricket net lanes over netball courts (retractable, 4 per court) | B10: 0 | C10: 8 | D10: 8 | E10: =CHOOSE($C$2,B10,C10,D10) | F10: Jan to Apr daytime dual use. 0 to switch off
A11: Bouldering room, sq m (option: replaces the 2 padel courts south of Court 3, ~460 sq m) | B11: 0 | C11: 0 | D11: 0 | E11: =CHOOSE($C$2,B11,C11,D11) | F11: Set padel to 3 if you use this. 4.5 m walls fit under 7.1 m eaves
A12: Operating weeks per year | B12: 50 | C12: 50 | D12: 50 | E12: =CHOOSE($C$2,B12,C12,D12)
A13: Physio / clinic rooms (in the offices) | B13: 2 | C13: 2 | D13: 2 | E13: =CHOOSE($C$2,B13,C13,D13)
A15: Netball — external hire (clubs, ADNA, Hampshire, schools). Momentum's own use is excluded below
A16: Evening court-hours per court per week (18:00–22:00 x 5) | B16: 20 | C16: 20 | D16: 20 | E16: =CHOOSE($C$2,B16,C16,D16)
A17: Court-hours per week Momentum uses in the evening | B17: 30 | C17: 30 | D17: 30 | E17: =CHOOSE($C$2,B17,C17,D17) | F17: 40 matches x 40 min today = ~27
A18: Evening fill of the remaining hours | B18: 0.55 | C18: 0.7 | D18: 0.8 | E18: =CHOOSE($C$2,B18,C18,D18)
A19: Evening rate per court-hour | B19: 42 | C19: 48 | D19: 52 | E19: =CHOOSE($C$2,B19,C19,D19)
A20: Weekend court-hours per court per week (10 x 2) | B20: 20 | C20: 20 | D20: 20 | E20: =CHOOSE($C$2,B20,C20,D20)
A21: Weekend fill | B21: 0.3 | C21: 0.45 | D21: 0.55 | E21: =CHOOSE($C$2,B21,C21,D21)
A22: Weekend rate per court-hour | B22: 38 | C22: 42 | D22: 45 | E22: =CHOOSE($C$2,B22,C22,D22)
A23: Weekday daytime court-hours per court per week (8 x 5) | B23: 40 | C23: 40 | D23: 40 | E23: =CHOOSE($C$2,B23,C23,D23)
A24: Daytime fill (schools, walking netball, Mini Momentum) | B24: 0.12 | C24: 0.2 | D24: 0.28 | E24: =CHOOSE($C$2,B24,C24,D24)
A25: Daytime rate per court-hour | B25: 26 | C25: 30 | D25: 32 | E25: =CHOOSE($C$2,B25,C25,D25)
A27: Momentum programmes moved in-house (leagues, mixed, pay to play, Netball Hour, walking, coaching)
A28: Momentum model: 1 = CIC runs the programmes, 2 = Momentum Netball Ltd rents courts from the CIC | B28: 2 | C28: 2 | D28: 2 | E28: =CHOOSE($C$2,B28,C28,D28) | F28: Mode 2 keeps Momentum Ltd independent; the CIC must charge it an arm's-length rate
A29: Mode 1: steady-state programme income inside the CIC | B29: 90000 | C29: 120000 | D29: 160000 | E29: =CHOOSE($C$2,B29,C29,D29) | F29: Xero FY26: £55k across all programmes on ~20 court-hours/week
A30: Mode 2: block-booking discount available to any block booker | B30: 0.15 | C30: 0.15 | D30: 0.15 | E30: =CHOOSE($C$2,B30,C30,D30) | F30: Same 15% as the 2025 sheet; must be offered to all, not just Momentum
A31: Mode 2: weeks per year Momentum books | B31: 40 | C31: 40 | D31: 40 | E31: =CHOOSE($C$2,B31,C31,D31)
A33: Padel
A34: Hours open per court per week (07:00–22:00 x 7) | B34: 105 | C34: 105 | D34: 105 | E34: =CHOOSE($C$2,B34,C34,D34)
A35: Blended fill | B35: 0.35 | C35: 0.45 | D35: 0.55 | E35: =CHOOSE($C$2,B35,C35,D35) | F35: UK indoor padel typically 50–65% by year 2
A36: Blended rate per court-hour | B36: 32 | C36: 36 | D36: 40 | E36: =CHOOSE($C$2,B36,C36,D36)
A38: Pickleball
A39: Hours open per court per week (12 x 7) | B39: 84 | C39: 84 | D39: 84 | E39: =CHOOSE($C$2,B39,C39,D39)
A40: Blended fill | B40: 0.25 | C40: 0.35 | D40: 0.45 | E40: =CHOOSE($C$2,B40,C40,D40)
A41: Rate per court-hour | B41: 18 | C41: 22 | D41: 26 | E41: =CHOOSE($C$2,B41,C41,D41)
A43: Winter cricket nets (dual use of netball courts, weekday daytime)
A44: Weeks per year (January to April) | B44: 16 | C44: 16 | D44: 16 | E44: =CHOOSE($C$2,B44,C44,D44)
A45: Lane-hours per lane per week (6 h x 5 days) | B45: 30 | C45: 30 | D45: 30 | E45: =CHOOSE($C$2,B45,C45,D45)
...

Sheet Structure
A1: Legal structure — what each one buys and costs
B3: Ltd company | C3: CIC (ltd by guarantee) | D3: Charity / CIO (trading sub for padel, café) | E3: CASC
A4: Mandatory 80% rates relief | B4: No | C4: No | D4: Yes (occupier must be the charity, use mainly charitable) | E4: Yes, +20% TVBC top-up = 100%
A5: TVBC discretionary relief | B5: No | C5: Up to 100% for a local non-profit recreation body; council bears 40% of the cost; needs 2 years' accounts | D5: Top-up to 100% possible | E5: Automatic 20%
A6: Gift Aid on donations (+25%) | B6: No | C6: No | D6: Yes | E6: Yes (limits apply)
A7: Grant access | B7: Very limited | C7: Lottery Reaching Communities, Football Foundation multi-sport, Sport England, TVBC S106 | D7: All of CIC plus charity-only trusts (Garfield Weston, Bernard Sunley, Wolfson) | E7: Sport England, Football Foundation; many trusts exclude CASCs
A8: Loans | B8: Commercial only | C8: Charity Bank, Triodos, Pitch Together (6%), LTA padel loan (5%) | D8: Same, usually better terms | E8: Same
A9: Community share offer | B9: No | C9: Not the true form; CIC ltd by shares can issue capped-dividend shares | D9: No (a charitable Bencom can) | E9: No
A10: Directors paid | B10: Yes | C10: Yes | D10: Trustees unpaid; founders become employees | E10: Officers usually unpaid
A11: Trading limits | B11: None | C11: None (asset lock on surplus) | D11: Non-primary-purpose trading via subsidiary | E11: Trading turnover cap £100k; property income cap
A12: Time to set up | B12: Days | C12: Weeks | D12: 3–6 months (Charity Commission) | E12: Weeks (HMRC)
A13: Fit for a £1.5m venue | B13: Only with investors | C13: Yes as operating company; weak on rates and Gift Aid | D13: Yes; best money, least founder control | E13: No — trading caps
A14: Rates relief % used by this model | B14: 0 | C14: 0 | D14: 0.8 | E14: 1
A15: Gift Aid flag used by this model | B15: 0 | C15: 0 | D15: 1 | E15: 1
A17: Active rates relief | B17: =IF(ISNUMBER(Inputs!$E$92),Inputs!$E$92,INDEX($B$14:$E$14,1,Inputs!$C$3))
A18: Active Gift Aid flag | B18: =INDEX($B$15:$E$15,1,Inputs!$C$3)
A20: Recommendation: CIC now for speed and paid directors, and apply to TVBC for discretionary relief on day one. Convert the venue-holding entity to a CIO once trading, or found the CIO in parallel so grants and Gift Aid land in it. The rates line is worth more than any single revenue line.

Sheet Steady state
A1: Steady-state annual P&L (year 3 income, full rent)
A2: Line | B2: £ per year | C2: How it is built
A3: Income
A4: Netball — evening external hire | B4: =(Inputs!$E$7*Inputs!$E$16-Inputs!$E$17)*Inputs!$E$18*Inputs!$E$19*Inputs!$E$12 | C4: (courts x 20 h − Momentum's hours) x fill x rate x weeks
A5: Netball — weekend hire | B5: =Inputs!$E$7*Inputs!$E$20*Inputs!$E$21*Inputs!$E$22*Inputs!$E$12
A6: Netball — daytime hire | B6: =Inputs!$E$7*Inputs!$E$23*Inputs!$E$24*Inputs!$E$25*Inputs!$E$12
A7: Momentum: programmes (mode 1) or court hire paid by Momentum Ltd (mode 2) | B7: =IF(Inputs!$E$28=1,Inputs!$E$29,Inputs!$E$17*Inputs!$E$19*(1-Inputs!$E$30)*Inputs!$E$31) | C7: mode 2 = Momentum's evening court-hours x evening rate x (1 − block discount) x weeks
A8: Padel court hire | B8: =Inputs!$E$8*Inputs!$E$34*Inputs!$E$35*Inputs!$E$36*Inputs!$E$12
A9: Pickleball court hire | B9: =Inputs!$E$9*Inputs!$E$39*Inputs!$E$40*Inputs!$E$41*Inputs!$E$12
A10: Winter cricket nets | B10: =Inputs!$E$10*Inputs!$E$45*Inputs!$E$46*Inputs!$E$47*Inputs!$E$44
A11: Bouldering room | B11: =Inputs!$E$11*Inputs!$E$50
A12: Gym memberships | B12: =Inputs!$E$54*Inputs!$E$55*12
A13: Netball S&C and injury-prevention classes | B13: =Inputs!$E$56*Inputs!$E$57*Inputs!$E$58*Inputs!$E$12
A14: Physio rooms and programmes | B14: =Inputs!$E$13*Inputs!$E$61*12+Inputs!$E$62
A15: Café and bar sales | B15: =Inputs!$E$65*Inputs!$E$66*Inputs!$E$12
A16: Tournaments and events | B16: =Inputs!$E$70*Inputs!$E$71
A17: Holiday camps (Mini Momentum) | B17: =Inputs!$E$72*Inputs!$E$73*Inputs!$E$74*5
A18: Parties | B18: =Inputs!$E$75*Inputs!$E$76*Inputs!$E$12
A19: Meeting room hire | B19: =Inputs!$E$77
A20: Sponsorship and naming | B20: =Inputs!$E$80+Inputs!$E$81*Inputs!$E$82+Inputs!$E$83
A21: Donations (+ Gift Aid if charity/CASC) | B21: =Inputs!$E$84*(1+0.25*Structure!$B$18)
A22: Total income | B22: =SUM(B4:B21)
A23: Occupancy
A24: Rent | B24: =Inputs!$E$87
A25: Business rates after relief | B25: =Inputs!$E$90*Inputs!$E$91*(1-Structure!$B$17) | C25: RV x multiplier x (1 − relief from Structure sheet)
A26: Insurance | B26: =Inputs!$E$93
A27: Repairs and maintenance (FRI) | B27: =Inputs!$E$94
A28: Utilities net of PV | B28: =Inputs!$E$95-Inputs!$E$96
A29: Total occupancy | B29: =SUM(B24:B28)
A30: Staff
A31: Salaried staff | B31: =(Inputs!$E$99+Inputs!$E$100*Inputs!$E$101+Inputs!$E$102*Inputs!$E$103+Inputs!$E$104*Inputs!$E$105+Inputs!$E$106)*(1+Inputs!$E$108)
A32: Coaches and S&C (variable; programme coaching only in mode 1) | B32: =(IF(Inputs!$E$28=1,B7,0)+B13)*Inputs!$E$107*(1+Inputs!$E$108)
A33: Bouldering staff (only if the room exists) | B33: =IF(Inputs!$E$11>0,Inputs!$E$51*(1+Inputs!$E$108),0)
A34: Total staff | B34: =B31+B32+B33
A35: Other operating
A36: Café cost of sales | B36: =B15*(1-Inputs!$E$67)
A37: Booking, payments, software | B37: =B22*Inputs!$E$112
A38: Marketing | B38: =Inputs!$E$113
A39: Professional fees | B39: =Inputs!$E$114
A40: Equipment and consumables | B40: =Inputs!$E$115
...

Sheet 5 year
A1: Five-year P&L with ramp, rent-free period and stepped rent
B2: Year 1 | C2: Year 2 | D2: Year 3 | E2: Year 4 | F2: Year 5 | G2: 5-yr total
A3: Income (steady state x ramp; sponsorship and donations unramped) | B3: =('Steady state'!$B$22-'Steady state'!$B$20-'Steady state'!$B$21)*Inputs!$E$119+'Steady state'!$B$20+'Steady state'!$B$21 | C3: =('Steady state'!$B$22-'Steady state'!$B$20-'Steady state'!$B$21)*Inputs!$E$120+'Steady state'!$B$20+'Steady state'!$B$21 | D3: =('Steady state'!$B$22-'Steady state'!$B$20-'Steady state'!$B$21)*Inputs!$E$121+'Steady state'!$B$20+'Steady state'!$B$21 | E3: =('Steady state'!$B$22-'Steady state'!$B$20-'Steady state'!$B$21)*Inputs!$E$122+'Steady state'!$B$20+'Steady state'!$B$21 | F3: =('Steady state'!$B$22-'Steady state'!$B$20-'Steady state'!$B$21)*Inputs!$E$123+'Steady state'!$B$20+'Steady state'!$B$21 | G3: =SUM(B3:F3)
A4: Rent | B4: =-'Steady state'!$B$24*(12-Inputs!$E$88)/12 | C4: =-'Steady state'!$B$24*Inputs!$E$89 | D4: =-'Steady state'!$B$24*1 | E4: =-'Steady state'!$B$24*1 | F4: =-'Steady state'!$B$24*1 | G4: =SUM(B4:F4)
A5: Rates after relief | B5: =-'Steady state'!$B$25 | C5: =-'Steady state'!$B$25 | D5: =-'Steady state'!$B$25 | E5: =-'Steady state'!$B$25 | F5: =-'Steady state'!$B$25 | G5: =SUM(B5:F5)
A6: Insurance, repairs, utilities | B6: =-('Steady state'!$B$26+'Steady state'!$B$27+'Steady state'!$B$28) | C6: =-('Steady state'!$B$26+'Steady state'!$B$27+'Steady state'!$B$28) | D6: =-('Steady state'!$B$26+'Steady state'!$B$27+'Steady state'!$B$28) | E6: =-('Steady state'!$B$26+'Steady state'!$B$27+'Steady state'!$B$28) | F6: =-('Steady state'!$B$26+'Steady state'!$B$27+'Steady state'!$B$28) | G6: =SUM(B6:F6)
A7: Salaried staff (85% in year 1) | B7: =-'Steady state'!$B$31*0.85 | C7: =-'Steady state'!$B$31*1 | D7: =-'Steady state'!$B$31*1 | E7: =-'Steady state'!$B$31*1 | F7: =-'Steady state'!$B$31*1 | G7: =SUM(B7:F7)
A8: Coaches (scale with programmes) | B8: =-'Steady state'!$B$32*Inputs!$E$119 | C8: =-'Steady state'!$B$32*Inputs!$E$120 | D8: =-'Steady state'!$B$32*Inputs!$E$121 | E8: =-'Steady state'!$B$32*Inputs!$E$122 | F8: =-'Steady state'!$B$32*Inputs!$E$123 | G8: =SUM(B8:F8)
A9: Café cost of sales (scales) | B9: =-'Steady state'!$B$36*Inputs!$E$119 | C9: =-'Steady state'!$B$36*Inputs!$E$120 | D9: =-'Steady state'!$B$36*Inputs!$E$121 | E9: =-'Steady state'!$B$36*Inputs!$E$122 | F9: =-'Steady state'!$B$36*Inputs!$E$123 | G9: =SUM(B9:F9)
A10: Software and payments (scales) | B10: =-'Steady state'!$B$37*Inputs!$E$119 | C10: =-'Steady state'!$B$37*Inputs!$E$120 | D10: =-'Steady state'!$B$37*Inputs!$E$121 | E10: =-'Steady state'!$B$37*Inputs!$E$122 | F10: =-'Steady state'!$B$37*Inputs!$E$123 | G10: =SUM(B10:F10)
A11: Marketing, professional fees, equipment (year 1 marketing x1.5) | B11: =-('Steady state'!$B$38*1.5+'Steady state'!$B$39+'Steady state'!$B$40) | C11: =-('Steady state'!$B$38*1+'Steady state'!$B$39+'Steady state'!$B$40) | D11: =-('Steady state'!$B$38*1+'Steady state'!$B$39+'Steady state'!$B$40) | E11: =-('Steady state'!$B$38*1+'Steady state'!$B$39+'Steady state'!$B$40) | F11: =-('Steady state'!$B$38*1+'Steady state'!$B$39+'Steady state'!$B$40) | G11: =SUM(B11:F11)
A12: Contingency | B12: =-'Steady state'!$B$41*Inputs!$E$119 | C12: =-'Steady state'!$B$41*Inputs!$E$120 | D12: =-'Steady state'!$B$41*Inputs!$E$121 | E12: =-'Steady state'!$B$41*Inputs!$E$122 | F12: =-'Steady state'!$B$41*Inputs!$E$123 | G12: =SUM(B12:F12)
A13: Surplus before loan repayments | B13: =SUM(B3:B12) | C13: =SUM(C3:C12) | D13: =SUM(D3:D12) | E13: =SUM(E3:E12) | F13: =SUM(F3:F12) | G13: =SUM(B13:F13)
A14: Loan repayments | B14: =-Capital!$B$43 | C14: =-Capital!$B$43 | D14: =-Capital!$B$43 | E14: =-Capital!$B$43 | F14: =-Capital!$B$43 | G14: =SUM(B14:F14)
A15: Surplus / (deficit) | B15: =B13+B14 | C15: =C13+C14 | D15: =D13+D14 | E15: =E13+E14 | F15: =F13+F14 | G15: =SUM(B15:F15)
A16: Cumulative | B16: =SUM($B$15:B15) | C16: =SUM($B$15:C15) | D16: =SUM($B$15:D15) | E16: =SUM($B$15:E15) | F16: =SUM($B$15:F15) | G16: =SUM(B16:F16)
A19: Working capital needed = the most negative cumulative figure above, plus a buffer. It goes into the Capital sheet.
A20: Minimum cumulative | B20: =MIN(B16:F16)

Sheet Capital
A1: Capital need and funding stack
A2: Uses | B2: £ | C2: Basis
A3: Sports floor, netball courts (630 sq m each at £110/sq m) | B3: =Inputs!$E$7*630*110 | C3: Area-elastic sports floor with line marking
A4: Padel courts, indoor, installed | B4: =Inputs!$E$8*45000 | C4: £35–50k per court
A5: Pickleball courts, cricket nets, bouldering room | B5: =Inputs!$E$9*8000+Inputs!$E$10*4000+Inputs!$E$11*700 | C5: £8k per pickleball court on the sports floor; £4k per retractable lane; £700/sq m bouldering
A6: Gym fit-out and equipment (~210 sq m in the span A end) | B6: 100000
A7: Heating and ventilation for occupied sport | B7: 150000
A8: Changing rooms, café, reception, partitions | B8: 300000 | C8: Existing WCs and showers reduce this
A9: Netball posts, nets, curtains, lighting changes, scoreboards | B9: 60000
A10: Physio rooms and office conversion | B10: 40000
A11: IT, booking system, access control, AV | B11: 40000
A12: Planning, design and professional fees (12%) | B12: =SUM(B3:B11)*0.12
A13: Contingency (10%) | B13: =SUM(B3:B12)*0.10
A14: Rent deposit or guarantee (6 months) | B14: =Inputs!$E$87/2 | C14: Negotiate a guarantee instead of cash
A15: Working capital for years 1–2 (from 5 year sheet, + £50k buffer) | B15: =MAX(0,-'5 year'!$B$20)+50000
A16: Total capital need | B16: =SUM(B3:B15)
A18: Sources (targets, not commitments) | B18: £ | C18: Route and status
A19: Landlord capital contribution | B19: 150000 | C19: Ask: unit empty since 2023; they refurbished at cost | D19: grant/equity
A20: Football Foundation multi-sport grassroots facilities | B20: 250000 | C20: Netball named as a beneficiary of the £98m/yr programme; apply via Hampshire FA / England Netball | D20: grant/equity
A21: National Lottery Community Fund — Reaching Communities | B21: 200000 | C21: £20k to £500k+; funds building work for CICs and charities | D21: grant/equity
A22: Test Valley BC — S106 / CIL sport contributions | B22: 150000 | C22: East Anton and Picket Twenty growth; strategy forecasts a 6–8 court hall need by 2036 | D22: grant/equity
A23: England Netball / Sport England | B23: 100000 | C23: Via the Netball Development Officer; EN has £21.2m from Sport England to 2029 | D23: grant/equity
A24: Armed Forces Covenant Fund Trust | B24: 50000 | C24: Army HQ is in Andover; family and wellbeing programmes | D24: grant/equity
A25: Charitable trusts (Garfield Weston, Bernard Sunley, Wolfson) | B25: 100000 | C25: Charity only | D25: grant/equity
A26: Local sports charity: seed for Phase 1 and match funding | B26: 25000 | C26: Known to Adam; pays the survey, pre-app and engineer so no director funds Phase 1 personally | D26: grant/equity
A27: Local private investors introduced by the charity (patient capital) | B27: 250000 | C27: Capped-dividend shares in a CIC ltd by shares, a rent-deposit guarantee, or donations via the charitable arm. If it comes as a 6% loan instead, add about £34k a year of service | D27: grant/equity
A28: Crowdfunder with Sport England match | B28: 30000 | C28: Match up to £15k; also a demand test | D28: grant/equity
A29: Donations, naming-rights advance | B29: 100000 | C29: Year-0 sponsorship paid up front | D29: grant/equity
A30: LTA padel loan (Quick Access / Facility Loan) | B30: 200000 | C30: £25k–£250k at 5%, up to 10 years | D30: loan
A31: Charity Bank / Triodos / Pitch Together loan | B31: 400000 | C31: Pitch Together £25k–£300k at 6%; Charity Bank larger | D31: loan
A33: Total grants, donations and equity | B33: =SUMIF(D19:D31,"grant/equity",B19:B31)
A34: Total loans | B34: =SUMIF(D19:D31,"loan",B19:B31)
A35: Total sources | B35: =B33+B34
A36: Surplus / (gap) | B36: =B35-B16
A38: Grants and donations as % of capital | B38: =B33/B16
A41: Loan service
A42: Loan principal | B42: =B34
A43: Annual repayment (annuity) | B43: =IF(B42=0,0,-PMT(Inputs!$E$126,Inputs!$E$127,B42))

Sheet Momentum Ltd
A1: Momentum Netball Ltd as a tenant of the CIC (mode 2)
A2: Today, school halls cost Momentum about £24 per court-hour. The CIC must charge an arm's-length rate, so Momentum's league margin changes. This sheet shows what has to move.
B5: Today (Xero FY26) | C5: In the CIC, same fees | D5: In the CIC, new fees
A6: Evening court-hours per week | B6: 20 | C6: =Inputs!$E$17 | D6: =Inputs!$E$17
A7: Weeks per year | B7: 30 | C7: =Inputs!$E$31 | D7: =Inputs!$E$31
A8: Rate per court-hour paid | B8: 24 | C8: =Inputs!$E$19*(1-Inputs!$E$30) | D8: =Inputs!$E$19*(1-Inputs!$E$30)
A9: Matches per court-hour | B9: 1.5 | C9: 1.5 | D9: 1.5
A10: Fee per team per match | B10: 18 | C10: 18 | D10: 25
A11: Other direct costs per match (umpires, insurance, prizes) | B11: 6 | C11: 6 | D11: 6
A13: Matches per year | B13: =B6*B7*B9 | C13: =C6*C7*C9 | D13: =D6*D7*D9
A14: League income (2 teams per match) | B14: =B13*2*B10 | C14: =C13*2*C10 | D14: =D13*2*D10
A15: Court hire paid | B15: =-B6*B7*B8 | C15: =-C6*C7*C8 | D15: =-D6*D7*D8
A16: Other direct costs | B16: =-B13*B11 | C16: =-C13*C11 | D16: =-D13*D11
A17: League gross profit | B17: =SUM(B14:B16) | C17: =SUM(C14:C16) | D17: =SUM(D14:D16)
A18: Gross margin | B18: =IF(B14=0,0,B17/B14) | C18: =IF(C14=0,0,C17/C14) | D18: =IF(D14=0,0,D17/D14)
A20: Reference points: Xero FY26 league sales £43,781 and venue hire £14,647. Commercial leagues (Play Netball, Go Mammoth) charge £8–10 per player per match, about £56–70 per team. Momentum's £18 per team per match is the cheapest in the market by a distance.
A24: Governance: directors common to Momentum Ltd and the CIC must declare the conflict, the CIC board needs independent members, and the court-hire contract must be at the published rate. Funders and the CIC Regulator look for exactly this.

Sheet Layout
A1: Spaces, from the Hollis as-built survey (TVBC 23/02973/FULLN, drawing 10250 C10)
A3: Space | B3: Clear size | C3: Base use | D3: Alternatives that fit | E3: Why
A4: Span A (west), x 13.5–34 m | B4: 20 m x 52.5 m | C4: Court 1 + gym (18 x 20 m end) | D4: Court + 2 pickleball; court + walking netball | E4: 18.25 m court fits a 20 m span with 0.9 m each side
A5: Span B, x 34–54 m | B5: 20 m x 52.5 m | C5: Court 2 + 2 pickleball (end) | D5: Court + gym; court + S&C studio | E5: Same span; end zone 18 x 20 m
A6: Span C incl. extension, x 54–75 m | B6: 21 m x 60.5 m | C6: Court 3 + 2 padel (21 x 22 m leftover) | D6: Court 3 + bouldering room (~460 sq m); court 3 + 4 cricket lanes year-round | E6: Only 21 m spans take a 20 m padel court
A7: East block, x 75–96 m | B7: 21 m x 33.5 m | C7: 3 padel | D7: Court 4 at league run-offs (33.5 m); 6 pickleball; futsal / small-sided | E7: Depends on the 75 m line: columns or beam
A8: Office block, ground | B8: x 62–96 m, 4 m deep + SE corner | C8: Café, reception, changing (existing WCs and showers)
A9: Office block, first floor | B9: 3,467 sq ft total offices | C9: Physio rooms, meeting rooms, admin | D9: Sublet a suite | E9: Air-conditioned, refurbished
A10: All netball courts, Jan–Apr weekdays | B10: 4 lanes per court | C10: Retractable cricket nets | D10: Archery, indoor athletics hire | E10: Fills the dead daytime without capex on new space
A13: Height: eaves and valleys 7.1 m at every column row, each span has its own ridge (about 8.1 m at a 6° pitch). Momentum's leagues play in 6.7 m school halls today; England Netball's 7.5 m is for affiliated competition venues.
A16: What was rejected and why: trampoline park and soft play (different operating model, insurance, staff-heavy); 5-a-side (competes with our own evening slots and with Goals/PowerLeague economics); esports and nursery (not sport, not us).

Sheet Notes
A1: Andover Community Netball Hub — Unit 28 North Way, Walworth Business Park. Model built 2026-09-09.
A3: What this model is: a test of whether a multi-activity community venue can carry £450k rent plus £192k rates. It is not a business plan and nothing in it is committed.
A5: Facts: 47,035 sq ft; 7.1 m eaves (England Netball wants 7.5 m); RV £400,000; freeholder Test Valley BC; landlord Mileway; empty since 2023.
A6: Momentum Netball actuals (Xero FY to 31 Aug 2026): turnover £55,154, loss £5,099, venue hire £14,647, net assets (£3,610).
A8: How to use: change C2 on Inputs for Low/Base/High. Change C3 for the legal structure; it drives rates relief and Gift Aid. Every yellow cell is an assumption.
A10: Momentum Netball Ltd can stay independent and block-book courts from the CIC (mode 2 on Inputs). The Momentum Ltd sheet shows the effect on its league margin: at an arm's-length rate its £18 per team per match no longer covers the court, so fees rise or the league grows.
A12: Layout is 3 netball + 5 padel + 2 pickleball + winter cricket nets by default (Layout sheet). Set boulder_sqm to ~460 and padel to 3 to test a bouldering room instead of the two padel courts south of Court 3.
A14: What the model says: at Base, as a CIC with no rates relief, the venue roughly breaks even at steady state before loan repayments and loses money in years 1–2. Charity status or TVBC discretionary relief is worth about £154k a year, more than any single income line. Padel and the café carry the daytime.
A16: Biggest unknowns, in order: clear height under the roof; ground-lease user clause and planning; landlord incentives; padel fill; whether the tenant gets the PV electricity; VAT on rent and on fit-out (a VAT-exempt sports body cannot recover it — take advice).
A18: Grant figures are targets from published programme ranges: Football Foundation multi-sport (£98m/yr UK, netball named); Lottery Reaching Communities (£20k–£500k typical); LTA loans £25k–£250k at 5%; Pitch Together £25k–£300k at 6%; TVBC discretionary relief up to 100% for local non-profit recreation bodies (policy v2026.1).
